Workbook

Sheet Assumptions
A1: JOULE FINANCIAL MODEL — ASSUMPTIONS
A3: SCENARIO SELECTOR
A4: Select Scenario: | C4: Base | H4: Choose: Worst / Base / Best (affects Total Funds Raised only)
A6: FEE STRUCTURE
A7: Upfront Fee Rate (% of Funds Raised) | C7: 0.02
A8: Completion Fee Rate (% of Funds Raised, total) | C8: 0.005
A9: Project Completion Time (Years, straight-line spread) | C9: 3
A10: kWh Fee Rate (£ per kWh) | C10: 0.01
A11: kWh Revenue Rate (% of Funds Raised, annual recurring) | C11: 0.0212
A12: kWh Contract Duration (Years, model shows 5 years only) | C12: 10
A14: BASE CASE — TOTAL FUNDS RAISED PER YEAR
A15: Year → | C15: 2026 | D15: 2027 | E15: 2028 | F15: 2029 | G15: 2030
A16: Total Funds Raised (Base Case) | C16: 18000000 | D16: 56000000 | E16: 150000000 | F16: 312000000 | G16: 576000000
A18: SCENARIO MULTIPLIERS (applied to Total Funds Raised)
A19: Worst Case Multiplier | C19: 0.6
A20: Best Case Multiplier | C20: 1.4
A22: COST OF GOODS SOLD (COGS)
A23: Year → | C23: 2026 | D23: 2027 | E23: 2028 | F23: 2029 | G23: 2030
A24: Smart Contract Deployment & Audits (£) | C24: 185000 | D24: 170000 | E24: 105000 | F24: 115000 | G24: 130000
A25: Hosting & API Costs (% of Gross Revenue) | C25: 0.015 | D25: (same % applies each year)
A27: OPERATING EXPENSES — YEAR 1 / 2026 (HARDCODED £)
A28: Salaries | C28: 225000
A29: Marketing & Growth | C29: 50000
A30: Legal & Regulatory | C30: 100000
A31: Insurance | C31: 20000
A32: R&D | C32: 50000
A34: OPERATING EXPENSES — YEARS 2–5 (% OF GROSS REVENUE)
A35: Year → | D35: 2027 | E35: 2028 | F35: 2029 | G35: 2030
A36: Salaries % | D36: 0.25 | E36: 0.25 | F36: 0.25 | G36: 0.25
A37: Marketing & Growth % | D37: 0.12 | E37: 0.07 | F37: 0.07 | G37: 0.07
A38: Legal & Regulatory % | D38: 0.08 | E38: 0.08 | F38: 0.08 | G38: 0.08
A39: Insurance % | D39: 0.02 | E39: 0.01 | F39: 0.01 | G39: 0.01
A40: R&D % | D40: 0.19 | E40: 0.11 | F40: 0.05 | G40: 0.05
A42: TAX ASSUMPTIONS
A43: Small Profits Rate (profits ≤ £50,000) | C43: 0.19
A44: Main Rate (profits > £250,000) | C44: 0.25
A45: Lower Profits Threshold (£) | C45: 50000
A46: Upper Profits Threshold (£) | C46: 250000
A47: Tax Payment Lag (months after year-end) | C47: 9
A48: Loss Carry-Forward Annual Deduction Limit (£) | C48: 5000000
...

Sheet Scenarios
A1: SCENARIOS — TOTAL FUNDS RAISED
A2: Scenarios only affect Total Funds Raised. All other assumptions remain constant.
A4: SCENARIO DATA TABLE
A5: Scenario | B5: Description | C5: 2026 | D5: 2027 | E5: 2028 | F5: 2029 | G5: 2030 | H5: Multiplier
A6: Worst | B6: Base × 0.6 (40% reduction in Funds Raised) | C6: =Assumptions!C16*Assumptions!C19 | D6: =Assumptions!D16*Assumptions!C19 | E6: =Assumptions!E16*Assumptions!C19 | F6: =Assumptions!F16*Assumptions!C19 | G6: =Assumptions!G16*Assumptions!C19 | H6: 0.6
A7: Base | B7: Central assumption — as per business plan | C7: =Assumptions!C16 | D7: =Assumptions!D16 | E7: =Assumptions!E16 | F7: =Assumptions!F16 | G7: =Assumptions!G16 | H7: 1.0
A8: Best | B8: Base × 1.4 (40% uplift in Funds Raised) | C8: =Assumptions!C16*Assumptions!C20 | D8: =Assumptions!D16*Assumptions!C20 | E8: =Assumptions!E16*Assumptions!C20 | F8: =Assumptions!F16*Assumptions!C20 | G8: =Assumptions!G16*Assumptions!C20 | H8: 1.4
A10: ACTIVE SCENARIO (driven by Assumptions!C4 dropdown)
A11: Scenario → | B11: =Assumptions!C4
A12: Funds Raised | B12: (Active) | C12: =INDEX($C$6:$G$8,MATCH(Assumptions!$C$4,$A$6:$A$8,0),1) | D12: =INDEX($C$6:$G$8,MATCH(Assumptions!$C$4,$A$6:$A$8,0),2) | E12: =INDEX($C$6:$G$8,MATCH(Assumptions!$C$4,$A$6:$A$8,0),3) | F12: =INDEX($C$6:$G$8,MATCH(Assumptions!$C$4,$A$6:$A$8,0),4) | G12: =INDEX($C$6:$G$8,MATCH(Assumptions!$C$4,$A$6:$A$8,0),5)

Sheet Income Statement
A1: INCOME STATEMENT
A2: All figures in GBP (£)
A3: Year → | C3: 2026 | D3: 2027 | E3: 2028 | F3: 2029 | G3: 2030
A5: REVENUE
A6: Total Funds Raised (Active Scenario) | C6: =Scenarios!C12 | D6: =Scenarios!D12 | E6: =Scenarios!E12 | F6: =Scenarios!F12 | G6: =Scenarios!G12
A7: Upfront Fee Revenue (2% of Funds Raised) | B7: → IS | C7: =Assumptions!$C$7*'Income Statement'!C6 | D7: =Assumptions!$C$7*'Income Statement'!D6 | E7: =Assumptions!$C$7*'Income Statement'!E6 | F7: =Assumptions!$C$7*'Income Statement'!F6 | G7: =Assumptions!$C$7*'Income Statement'!G6
A8: Completion Fee Revenue (0.5% over 3-yr build, straight-line) | C8: =(Assumptions!$C$8/Assumptions!$C$9)*('Income Statement'!C6) | D8: =(Assumptions!$C$8/Assumptions!$C$9)*('Income Statement'!C6+D6) | E8: =(Assumptions!$C$8/Assumptions!$C$9)*('Income Statement'!C6+D6+E6) | F8: =(Assumptions!$C$8/Assumptions!$C$9)*('Income Statement'!D6+E6+F6) | G8: =(Assumptions!$C$8/Assumptions!$C$9)*('Income Statement'!E6+F6+G6)
A9: kWh Revenue (2.12% of Funds, 3-yr lag, cumulative cohorts) | C9: 0 | D9: 0 | E9: 0 | F9: =Assumptions!$C$11*'Income Statement'!C6 | G9: =Assumptions!$C$11*('Income Statement'!C6+'Income Statement'!D6)
A10: TOTAL GROSS REVENUE | C10: =SUM('Income Statement'!C7:C9) | D10: =SUM('Income Statement'!D7:D9) | E10: =SUM('Income Statement'!E7:E9) | F10: =SUM('Income Statement'!F7:F9) | G10: =SUM('Income Statement'!G7:G9)
A12: COST OF GOODS SOLD (COGS)
A13: Smart Contract Deployment & Audits | C13: =Assumptions!C24 | D13: =Assumptions!D24 | E13: =Assumptions!E24 | F13: =Assumptions!F24 | G13: =Assumptions!G24
A14: Hosting & API Costs (1.5% of Gross Revenue) | C14: =Assumptions!$C$25*'Income Statement'!C10 | D14: =Assumptions!$C$25*'Income Statement'!D10 | E14: =Assumptions!$C$25*'Income Statement'!E10 | F14: =Assumptions!$C$25*'Income Statement'!F10 | G14: =Assumptions!$C$25*'Income Statement'!G10
A15: TOTAL COGS | C15: =SUM('Income Statement'!C13:C14) | D15: =SUM('Income Statement'!D13:D14) | E15: =SUM('Income Statement'!E13:E14) | F15: =SUM('Income Statement'!F13:F14) | G15: =SUM('Income Statement'!G13:G14)
A17: GROSS PROFIT | C17: ='Income Statement'!C10-'Income Statement'!C15 | D17: ='Income Statement'!D10-'Income Statement'!D15 | E17: ='Income Statement'!E10-'Income Statement'!E15 | F17: ='Income Statement'!F10-'Income Statement'!F15 | G17: ='Income Statement'!G10-'Income Statement'!G15
A19: OPERATING EXPENSES
A20: Salaries | C20: =Assumptions!$C$28 | D20: =Assumptions!D36*'Income Statement'!D10 | E20: =Assumptions!E36*'Income Statement'!E10 | F20: =Assumptions!F36*'Income Statement'!F10 | G20: =Assumptions!G36*'Income Statement'!G10
A21: Marketing & Growth | C21: =Assumptions!$C$29 | D21: =Assumptions!D37*'Income Statement'!D10 | E21: =Assumptions!E37*'Income Statement'!E10 | F21: =Assumptions!F37*'Income Statement'!F10 | G21: =Assumptions!G37*'Income Statement'!G10
A22: Legal & Regulatory | C22: =Assumptions!$C$30 | D22: =Assumptions!D38*'Income Statement'!D10 | E22: =Assumptions!E38*'Income Statement'!E10 | F22: =Assumptions!F38*'Income Statement'!F10 | G22: =Assumptions!G38*'Income Statement'!G10
A23: Insurance | C23: =Assumptions!$C$31 | D23: =Assumptions!D39*'Income Statement'!D10 | E23: =Assumptions!E39*'Income Statement'!E10 | F23: =Assumptions!F39*'Income Statement'!F10 | G23: =Assumptions!G39*'Income Statement'!G10
A24: R&D | C24: =Assumptions!$C$32 | D24: =Assumptions!D40*'Income Statement'!D10 | E24: =Assumptions!E40*'Income Statement'!E10 | F24: =Assumptions!F40*'Income Statement'!F10 | G24: =Assumptions!G40*'Income Statement'!G10
A25: TOTAL OPERATING EXPENSES | C25: =SUM('Income Statement'!C20:C24) | D25: =SUM('Income Statement'!D20:D24) | E25: =SUM('Income Statement'!E20:E24) | F25: =SUM('Income Statement'!F20:F24) | G25: =SUM('Income Statement'!G20:G24)
A27: EBIT (Operating Profit / Loss) | C27: ='Income Statement'!C17-'Income Statement'!C25 | D27: ='Income Statement'!D17-'Income Statement'!D25 | E27: ='Income Statement'!E17-'Income Statement'!E25 | F27: ='Income Statement'!F17-'Income Statement'!F25 | G27: ='Income Statement'!G17-'Income Statement'!G25
A29: UK CORPORATION TAX COMPUTATION
A30: Prior-Year Tax Loss Balance (b/f) | C30: =0 | D30: ='Income Statement'!C34 | E30: ='Income Statement'!D34 | F30: ='Income Statement'!E34 | G30: ='Income Statement'!F34
A31: Loss Carry-Forward Applied (limited to £5M p.a. & actual profit) | C31: =IF('Income Statement'!C27>0,MIN('Income Statement'!C30,Assumptions!$C$48,'Income Statement'!C27),0) | D31: =IF('Income Statement'!D27>0,MIN('Income Statement'!D30,Assumptions!$C$48,'Income Statement'!D27),0) | E31: =IF('Income Statement'!E27>0,MIN('Income Statement'!E30,Assumptions!$C$48,'Income Statement'!E27),0) | F31: =IF('Income Statement'!F27>0,MIN('Income Statement'!F30,Assumptions!$C$48,'Income Statement'!F27),0) | G31: =IF('Income Statement'!G27>0,MIN('Income Statement'!G30,Assumptions!$C$48,'Income Statement'!G27),0)
A32: Taxable Profit After Loss Relief | C32: =MAX('Income Statement'!C27-'Income Statement'!C31,0) | D32: =MAX('Income Statement'!D27-'Income Statement'!D31,0) | E32: =MAX('Income Statement'!E27-'Income Statement'!E31,0) | F32: =MAX('Income Statement'!F27-'Income Statement'!F31,0) | G32: =MAX('Income Statement'!G27-'Income Statement'!G31,0)
A33: Tax Provision (19% / marginal relief / 25%) | C33: =IF('Income Statement'!C32<=0,0,IF('Income Statement'!C32<=Assumptions!$C$45,Assumptions!$C$43*'Income Statement'!C32,IF('Income Statement'!C32<=Assumptions!$C$46,Assumptions!$C$44*'Income Statement'!C32-(Assumptions!$C$46-'Income Statement'!C32)*3/200,Assumptions!$C$44*'Income Statement'!C32))) | D33: =IF('Income Statement'!D32<=0,0,IF('Income Statement'!D32<=Assumptions!$C$45,Assumptions!$C$43*'Income Statement'!D32,IF('Income Statement'!D32<=Assumptions!$C$46,Assumptions!$C$44*'Income Statement'!D32-(Assumptions!$C$46-'Income Statement'!D32)*3/200,Assumptions!$C$44*'Income Statement'!D32))) | E33: =IF('Income Statement'!E32<=0,0,IF('Income Statement'!E32<=Assumptions!$C$45,Assumptions!$C$43*'Income Statement'!E32,IF('Income Statement'!E32<=Assumptions!$C$46,Assumptions!$C$44*'Income Statement'!E32-(Assumptions!$C$46-'Income Statement'!E32)*3/200,Assumptions!$C$44*'Income Statement'!E32))) | F33: =IF('Income Statement'!F32<=0,0,IF('Income Statement'!F32<=Assumptions!$C$45,Assumptions!$C$43*'Income Statement'!F32,IF('Income Statement'!F32<=Assumptions!$C$46,Assumptions!$C$44*'Income Statement'!F32-(Assumptions!$C$46-'Income Statement'!F32)*3/200,Assumptions!$C$44*'Income Statement'!F32))) | G33: =IF('Income Statement'!G32<=0,0,IF('Income Statement'!G32<=Assumptions!$C$45,Assumptions!$C$43*'Income Statement'!G32,IF('Income Statement'!G32<=Assumptions!$C$46,Assumptions!$C$44*'Income Statement'!G32-(Assumptions!$C$46-'Income Statement'!G32)*3/200,Assumptions!$C$44*'Income Statement'!G32)))
A34: Closing Tax Loss Balance (carried forward to next year) | C34: =MAX(0,'Income Statement'!C30-'Income Statement'!C31)+MAX(0,-'Income Statement'!C27) | D34: =MAX(0,'Income Statement'!D30-'Income Statement'!D31)+MAX(0,-'Income Statement'!D27) | E34: =MAX(0,'Income Statement'!E30-'Income Statement'!E31)+MAX(0,-'Income Statement'!E27) | F34: =MAX(0,'Income Statement'!F30-'Income Statement'!F31)+MAX(0,-'Income Statement'!F27) | G34: =MAX(0,'Income Statement'!G30-'Income Statement'!G31)+MAX(0,-'Income Statement'!G27)
A36: NET INCOME (After Tax) | C36: ='Income Statement'!C27-'Income Statement'!C33 | D36: ='Income Statement'!D27-'Income Statement'!D33 | E36: ='Income Statement'!E27-'Income Statement'!E33 | F36: ='Income Statement'!F27-'Income Statement'!F33 | G36: ='Income Statement'!G27-'Income Statement'!G33

Sheet Balance Sheet
A1: BALANCE SHEET
A2: All figures in GBP (£)
A3: Year → | C3: 2026 | D3: 2027 | E3: 2028 | F3: 2029 | G3: 2030
A5: ASSETS
A6: Cash & Cash Equivalents | C6: ='Cash Flow'!C23 | D6: ='Cash Flow'!D23 | E6: ='Cash Flow'!E23 | F6: ='Cash Flow'!F23 | G6: ='Cash Flow'!G23
A7: Accounts Receivable (Revenue × DSO / 365) | C7: ='Income Statement'!C10*Assumptions!$C$55/365 | D7: ='Income Statement'!D10*Assumptions!$C$55/365 | E7: ='Income Statement'!E10*Assumptions!$C$55/365 | F7: ='Income Statement'!F10*Assumptions!$C$55/365 | G7: ='Income Statement'!G10*Assumptions!$C$55/365
A8: TOTAL CURRENT ASSETS | C8: =SUM('Balance Sheet'!C6:C7) | D8: =SUM('Balance Sheet'!D6:D7) | E8: =SUM('Balance Sheet'!E6:E7) | F8: =SUM('Balance Sheet'!F6:F7) | G8: =SUM('Balance Sheet'!G6:G7)
A9: TOTAL ASSETS | C9: ='Balance Sheet'!C8 | D9: ='Balance Sheet'!D8 | E9: ='Balance Sheet'!E8 | F9: ='Balance Sheet'!F8 | G9: ='Balance Sheet'!G8
A11: LIABILITIES
A12: Accounts Payable ((COGS + OpEx) × DPO / 365) | C12: =('Income Statement'!C15+'Income Statement'!C25)*Assumptions!$C$56/365 | D12: =('Income Statement'!D15+'Income Statement'!D25)*Assumptions!$C$56/365 | E12: =('Income Statement'!E15+'Income Statement'!E25)*Assumptions!$C$56/365 | F12: =('Income Statement'!F15+'Income Statement'!F25)*Assumptions!$C$56/365 | G12: =('Income Statement'!G15+'Income Statement'!G25)*Assumptions!$C$56/365
A13: Corporation Tax Payable (current year provision, paid next year) | C13: ='Income Statement'!C33 | D13: ='Income Statement'!D33 | E13: ='Income Statement'!E33 | F13: ='Income Statement'!F33 | G13: ='Income Statement'!G33
A14: TOTAL CURRENT LIABILITIES | C14: =SUM('Balance Sheet'!C12:C13) | D14: =SUM('Balance Sheet'!D12:D13) | E14: =SUM('Balance Sheet'!E12:E13) | F14: =SUM('Balance Sheet'!F12:F13) | G14: =SUM('Balance Sheet'!G12:G13)
A15: TOTAL LIABILITIES | C15: ='Balance Sheet'!C14 | D15: ='Balance Sheet'!D14 | E15: ='Balance Sheet'!E14 | F15: ='Balance Sheet'!F14 | G15: ='Balance Sheet'!G14
A17: EQUITY
A18: Share Capital (cumulative equity raises to date) | C18: =Assumptions!C52 | D18: ='Balance Sheet'!C18+Assumptions!D52 | E18: ='Balance Sheet'!D18+Assumptions!E52 | F18: ='Balance Sheet'!E18+Assumptions!F52 | G18: ='Balance Sheet'!F18+Assumptions!G52
A19: Retained Earnings (cumulative net income) | C19: ='Income Statement'!C36 | D19: ='Balance Sheet'!C19+'Income Statement'!D36 | E19: ='Balance Sheet'!D19+'Income Statement'!E36 | F19: ='Balance Sheet'!E19+'Income Statement'!F36 | G19: ='Balance Sheet'!F19+'Income Statement'!G36
A20: TOTAL EQUITY | C20: =SUM('Balance Sheet'!C18:C19) | D20: =SUM('Balance Sheet'!D18:D19) | E20: =SUM('Balance Sheet'!E18:E19) | F20: =SUM('Balance Sheet'!F18:F19) | G20: =SUM('Balance Sheet'!G18:G19)
A22: BALANCE CHECK (Total Assets − Total Liabilities − Total Equity = 0) | C22: ='Balance Sheet'!C9-'Balance Sheet'!C15-'Balance Sheet'!C20 | D22: ='Balance Sheet'!D9-'Balance Sheet'!D15-'Balance Sheet'!D20 | E22: ='Balance Sheet'!E9-'Balance Sheet'!E15-'Balance Sheet'!E20 | F22: ='Balance Sheet'!F9-'Balance Sheet'!F15-'Balance Sheet'!F20 | G22: ='Balance Sheet'!G9-'Balance Sheet'!G15-'Balance Sheet'!G20

Sheet Cash Flow
A1: CASH FLOW STATEMENT (Indirect Method)
A2: All figures in GBP (£)
A3: Year → | C3: 2026 | D3: 2027 | E3: 2028 | F3: 2029 | G3: 2030
A5: OPERATING ACTIVITIES
A6: Net Income (after tax) | C6: ='Income Statement'!C36 | D6: ='Income Statement'!D36 | E6: ='Income Statement'!E36 | F6: ='Income Statement'!F36 | G6: ='Income Statement'!G36
A7: Change in Accounts Receivable (increase = cash outflow) | C7: =-('Balance Sheet'!C7-0) | D7: =-('Balance Sheet'!D7-'Balance Sheet'!C7) | E7: =-('Balance Sheet'!E7-'Balance Sheet'!D7) | F7: =-('Balance Sheet'!F7-'Balance Sheet'!E7) | G7: =-('Balance Sheet'!G7-'Balance Sheet'!F7)
A8: Change in Accounts Payable (increase = cash inflow) | C8: ='Balance Sheet'!C12-0 | D8: ='Balance Sheet'!D12-'Balance Sheet'!C12 | E8: ='Balance Sheet'!E12-'Balance Sheet'!D12 | F8: ='Balance Sheet'!F12-'Balance Sheet'!E12 | G8: ='Balance Sheet'!G12-'Balance Sheet'!F12
A9: Change in Corporation Tax Payable (current provision − prior paid) | C9: ='Balance Sheet'!C13-0 | D9: ='Balance Sheet'!D13-'Balance Sheet'!C13 | E9: ='Balance Sheet'!E13-'Balance Sheet'!D13 | F9: ='Balance Sheet'!F13-'Balance Sheet'!E13 | G9: ='Balance Sheet'!G13-'Balance Sheet'!F13
A10: NET CASH FROM OPERATIONS | C10: =SUM('Cash Flow'!C6:C9) | D10: =SUM('Cash Flow'!D6:D9) | E10: =SUM('Cash Flow'!E6:E9) | F10: =SUM('Cash Flow'!F6:F9) | G10: =SUM('Cash Flow'!G6:G9)
A12: INVESTING ACTIVITIES
A13: Capital Expenditure / CapEx (asset-light — £0) | C13: =-Assumptions!$C$62 | D13: =-Assumptions!$C$62 | E13: =-Assumptions!$C$62 | F13: =-Assumptions!$C$62 | G13: =-Assumptions!$C$62
A14: NET CASH FROM INVESTING | C14: ='Cash Flow'!C13 | D14: ='Cash Flow'!D13 | E14: ='Cash Flow'!E13 | F14: ='Cash Flow'!F13 | G14: ='Cash Flow'!G13
A16: FINANCING ACTIVITIES
A17: Equity Raised (per Assumptions) | C17: =Assumptions!C52 | D17: =Assumptions!D52 | E17: =Assumptions!E52 | F17: =Assumptions!F52 | G17: =Assumptions!G52
A18: NET CASH FROM FINANCING | C18: ='Cash Flow'!C17 | D18: ='Cash Flow'!D17 | E18: ='Cash Flow'!E17 | F18: ='Cash Flow'!F17 | G18: ='Cash Flow'!G17
A20: CASH SUMMARY
A21: Net Change in Cash | C21: ='Cash Flow'!C10+'Cash Flow'!C14+'Cash Flow'!C18 | D21: ='Cash Flow'!D10+'Cash Flow'!D14+'Cash Flow'!D18 | E21: ='Cash Flow'!E10+'Cash Flow'!E14+'Cash Flow'!E18 | F21: ='Cash Flow'!F10+'Cash Flow'!F14+'Cash Flow'!F18 | G21: ='Cash Flow'!G10+'Cash Flow'!G14+'Cash Flow'!G18
A22: Opening Cash | C22: =Assumptions!$C$59 | D22: ='Cash Flow'!C23 | E22: ='Cash Flow'!D23 | F22: ='Cash Flow'!E23 | G22: ='Cash Flow'!F23
A23: CLOSING CASH (= Balance Sheet: Cash & Cash Equivalents) | C23: ='Cash Flow'!C21+'Cash Flow'!C22 | D23: ='Cash Flow'!D21+'Cash Flow'!D22 | E23: ='Cash Flow'!E21+'Cash Flow'!E22 | F23: ='Cash Flow'!F21+'Cash Flow'!F22 | G23: ='Cash Flow'!G21+'Cash Flow'!G22
